<?xml version="1.0"?>
<robot name="my_robot">

    

    <material name="grey">
        <color rgba="0.5 0.5 0.5 1" />
    </material>

    <material name="red">
        <color rgba="0.5 0 0 1" />
    </material>


    <material name="blue">
        <color rgba="0 0 0.5 1" />
    </material>

    <link name="base_footprint" />

    
    <link name="base_link">
      <visual>
         <geometry>
              <box size="0.6 0.4 0.2" />
         </geometry>
         <origin xyz="0 0 0.1" rpy="0 0 0" />
         <material name="blue" />
      </visual>
    </link>
    
    <link name="front_sphere">
       <visual>
           <origin xyz="0 0 0" rpy="0 0 0" />
           <geometry>
              <sphere radius="0.05" />
           </geometry>
           <material name="red" />
       </visual>
   </link>

 

    <link name="left1_wheel_link">
       <visual>
          <geometry>
              <cylinder radius="0.1" length="0.05" />
          </geometry>
          <origin xyz="0 0 0" rpy="0 0 0" />
          <material name="grey" />
       </visual>
    </link>

    <link name="left2_wheel_link">
       <visual>
          <geometry>
              <cylinder radius="0.1" length="0.05" />
          </geometry>
          <origin xyz="0 0 0" rpy="0 0 0" />
          <material name="grey" />
       </visual>
    </link>


    <joint name="base_left1_wheel_joint" type="continuous" >
        <parent link="base_link" />
        <child link="left1_wheel_link" />
        <origin xyz="-0.15 -0.225 0" rpy="1.57 0 0" />
        <axis xyz="0 0 1" />
    </joint>


    <joint name="base_left2_wheel_joint" type="continuous" >
        <parent link="base_link" />
        <child link="left2_wheel_link" />
        <origin xyz="-0.15 0.225 0" rpy="1.57 0 0" />
        <axis xyz="0 0 1" />
    </joint>

    <joint name="base_sphere_joint" type="fixed" >
        <parent link="base_link" />
        <child link="front_sphere" />
        <origin xyz="0.2 0 -0.05" rpy="0 0 0" />
       
    </joint>

    <joint name="base_joint" type="fixed" >
       <parent link="base_footprint" />
       <child link="base_link" />
       <origin xyz="0 0 0.1" rpy="0 0 0" />
    </joint>
</robot>

<!-- ros2 launch urdf_tutorial display.launch.py model:=/home/yash-verma/my_robot.urdf -->